<?xml version="1.0" ?>
<!-- =================================================================================== -->
<!-- |    This document was autogenerated by xacro from thunder_demo.xacro             | -->
<!-- |    EDITING THIS FILE BY HAND IS NOT RECOMMENDED                                 | -->
<!-- =================================================================================== -->
<robot name="Thunder">
  <gazebo>
    <plugin filename="libgazebo_ros_control.so" name="gazebo_ros_control">
      <robotNamespace>/mobile_base</robotNamespace>
      <robotSimType>gazebo_ros_control/DefaultRobotHWSim</robotSimType>
    </plugin>
  </gazebo>
  <gazebo reference="base_link">
    <material>Gazebo/Black</material>
  </gazebo>
  <link name="base_link"/>
  <link name="chassis_base_link">
    <visual>
      <origin rpy="0 0 0" xyz="0 0 0"/>
      <geometry>
        <mesh filename="package://description_pkg/urdf/meshes/base_link.dae"/>
      </geometry>
    </visual>
    <collision>
      <origin rpy="0 0 0" xyz="0 0 0.008"/>
      <geometry>
        <box size="0.925 0.38 0.21"/>
      </geometry>
    </collision>
    <collision>
      <origin rpy="0 0 0" xyz="0 0 0.035"/>
      <geometry>
        <box size="0.154166666667 0.627 0.07"/>
      </geometry>
    </collision>
  </link>
  <joint name="base_joint" type="fixed">
    <origin rpy="0 0 0" xyz="0 0 0.236"/>
    <parent link="base_link"/>
    <child link="chassis_base_link"/>
    <axis xyz="0 0 0"/>
  </joint>
  <link name="inertial_link">
    <inertial>
      <mass value="40"/>
      <origin xyz="0.0 0.0 0.0"/>
      <inertia ixx="2.288641" ixy="0" ixz="0" iyy="5.103976" iyz="0" izz="3.431465"/>
    </inertial>
  </link>
  <joint name="inertial_joint" type="fixed">
    <origin rpy="0 0 0" xyz="0 0 0"/>
    <parent link="chassis_base_link"/>
    <child link="inertial_link"/>
  </joint>
  <link name="front_right_wheel_link">
    <inertial>
      <mass value="3"/>
      <origin xyz="0 0 0"/>
      <inertia ixx="0.7171" ixy="0" ixz="0" iyy="0.1361" iyz="0" izz="0.7171"/>
    </inertial>
    <visual>
      <origin rpy="0 0 0" xyz="0 0 0"/>
      <geometry>
        <mesh filename="package://description_pkg/urdf/meshes/wheel_type1.dae"/>
      </geometry>
    </visual>
    <collision>
      <origin rpy="1.570795 0 0" xyz="0 0 0"/>
      <geometry>
        <cylinder length="0.11653" radius="0.16459"/>
      </geometry>
    </collision>
  </link>
  <joint name="wheel2_joint" type="continuous">
    <parent link="chassis_base_link"/>
    <child link="front_right_wheel_link"/>
    <origin rpy="3.14 0 0" xyz="0.249 -0.29153 -0.0702"/>
    <axis rpy="0 0 0" xyz="0 -1 0"/>
  </joint>
  <link name="front_left_wheel_link">
    <inertial>
      <mass value="3"/>
      <origin xyz="0 0 0"/>
      <inertia ixx="0.7171" ixy="0" ixz="0" iyy="0.1361" iyz="0" izz="0.7171"/>
    </inertial>
    <visual>
      <origin rpy="0 0 0" xyz="0 0 0"/>
      <geometry>
        <mesh filename="package://description_pkg/urdf/meshes/wheel_type2.dae"/>
      </geometry>
    </visual>
    <collision>
      <origin rpy="1.570795 0 0" xyz="0 0 0"/>
      <geometry>
        <cylinder length="0.11653" radius="0.16459"/>
      </geometry>
    </collision>
  </link>
  <joint name="wheel1_joint" type="continuous">
    <parent link="chassis_base_link"/>
    <child link="front_left_wheel_link"/>
    <origin rpy="0 0 0" xyz="0.249 0.29153 -0.0702"/>
    <axis rpy="0 0 0" xyz="0 -1 0"/>
  </joint>
  <link name="rear_left_wheel_link">
    <inertial>
      <mass value="3"/>
      <origin xyz="0 0 0"/>
      <inertia ixx="0.7171" ixy="0" ixz="0" iyy="0.1361" iyz="0" izz="0.7171"/>
    </inertial>
    <visual>
      <origin rpy="0 0 0" xyz="0 0 0"/>
      <geometry>
        <mesh filename="package://description_pkg/urdf/meshes/wheel_type1.dae"/>
      </geometry>
    </visual>
    <collision>
      <origin rpy="1.570795 0 0" xyz="0 0 0"/>
      <geometry>
        <cylinder length="0.11653" radius="0.16459"/>
      </geometry>
    </collision>
  </link>
  <joint name="wheel3_joint" type="continuous">
    <parent link="chassis_base_link"/>
    <child link="rear_left_wheel_link"/>
    <origin rpy="0 0 0" xyz="-0.249 0.29153 -0.0702"/>
    <axis rpy="0 0 0" xyz="0 -1 0"/>
  </joint>
  <link name="rear_right_wheel_link">
    <inertial>
      <mass value="3"/>
      <origin xyz="0 0 0"/>
      <inertia ixx="0.7171" ixy="0" ixz="0" iyy="0.1361" iyz="0" izz="0.7171"/>
    </inertial>
    <visual>
      <origin rpy="0 0 0" xyz="0 0 0"/>
      <geometry>
        <mesh filename="package://description_pkg/urdf/meshes/wheel_type2.dae"/>
      </geometry>
    </visual>
    <collision>
      <origin rpy="1.570795 0 0" xyz="0 0 0"/>
      <geometry>
        <cylinder length="0.11653" radius="0.16459"/>
      </geometry>
    </collision>
  </link>
  <joint name="wheel4_joint" type="continuous">
    <parent link="chassis_base_link"/>
    <child link="rear_right_wheel_link"/>
    <origin rpy="3.14 0 0" xyz="-0.249 -0.29153 -0.0702"/>
    <axis rpy="0 0 0" xyz="0 -1 0"/>
  </joint>
  <transmission name="front_right_wheel_trans" type="SimpleTransmission">
    <type>transmission_interface/SimpleTransmission</type>
    <actuator name="front_right_wheel_motor">
      <mechanicalReduction>1</mechanicalReduction>
    </actuator>
    <joint name="wheel2_joint">
      <hardwareInterface>hardware_interface/VelocityJointInterface</hardwareInterface>
    </joint>
  </transmission>
  <transmission name="front_left_wheel_trans" type="SimpleTransmission">
    <type>transmission_interface/SimpleTransmission</type>
    <actuator name="front_left_wheel_motor">
      <mechanicalReduction>1</mechanicalReduction>
    </actuator>
    <joint name="wheel1_joint">
      <hardwareInterface>hardware_interface/VelocityJointInterface</hardwareInterface>
    </joint>
  </transmission>
  <transmission name="rear_left_wheel_trans" type="SimpleTransmission">
    <type>transmission_interface/SimpleTransmission</type>
    <actuator name="rear_left_wheel_motor">
      <mechanicalReduction>1</mechanicalReduction>
    </actuator>
    <joint name="wheel3_joint">
      <hardwareInterface>hardware_interface/VelocityJointInterface</hardwareInterface>
    </joint>
  </transmission>
  <transmission name="rear_right_wheel_trans" type="SimpleTransmission">
    <type>transmission_interface/SimpleTransmission</type>
    <actuator name="rear_right_wheel_motor">
      <mechanicalReduction>1</mechanicalReduction>
    </actuator>
    <joint name="wheel4_joint">
      <hardwareInterface>hardware_interface/VelocityJointInterface</hardwareInterface>
    </joint>
  </transmission>
  <!-- kp spring constant, kd damping constant -->
  <gazebo>
    <mu1 value="1.0"/>
    <mu2 value="0.9"/>
    <kp value="10000000.0"/>
    <kd value="1.0"/>
    <fdir1 value="1 0 0"/>
    <minDepth value="0.001"/>
    <maxContacts value="64"/>
  </gazebo>
  <link name="Navi_L_V1_link">
    <inertial>
      <origin rpy="0 0 0" xyz="0.019708 0.0011205 0.11592"/>
      <mass value="16.373"/>
      <inertia ixx="0.16697" ixy="0.0025757" ixz="-0.034051" iyy="0.46927" iyz="0.00011966" izz="0.51322"/>
    </inertial>
    <visual>
      <origin rpy="0 0 0" xyz="0 0 0"/>
      <geometry>
        <mesh filename="package://description_pkg/urdf/meshes/Navi_L_V1_link.STL"/>
      </geometry>
      <material name="">
        <color rgba="0.79216 0.81961 0.93333 1"/>
      </material>
    </visual>
    <collision>
      <origin rpy="0 0 0" xyz="0 0 0"/>
      <geometry>
        <mesh filename="package://description_pkg/urdf/meshes/Navi_L_V1_link.STL"/>
      </geometry>
    </collision>
  </link>
  <joint name="Navi_L_V1_joint" type="fixed">
    <origin rpy="0 0 0" xyz="0 0 0.34596"/>
    <parent link="base_link"/>
    <child link="Navi_L_V1_link"/>
    <axis xyz="0 0 0"/>
  </joint>
  <link name="4Gcamera_link">
    <inertial>
      <origin rpy="0 0 0" xyz="0.015392 -7.3061E-06 -3.9903E-05"/>
      <mass value="0.079186"/>
      <inertia ixx="0" ixy="0" ixz="0" iyy="0" iyz="0" izz="0"/>
    </inertial>
    <visual>
      <origin rpy="0 0 0" xyz="0 0 0"/>
      <geometry>
        <mesh filename="package://description_pkg/urdf/meshes/4Gcamera_link.STL"/>
      </geometry>
      <material name="">
        <color rgba="0.75294 0.75294 0.75294 1"/>
      </material>
    </visual>
    <collision>
      <origin rpy="0 0 0" xyz="0 0 0"/>
      <geometry>
        <mesh filename="package://description_pkg/urdf/meshes/4Gcamera_link.STL"/>
      </geometry>
    </collision>
  </link>
  <joint name="4Gcamera_joint" type="fixed">
    <origin rpy="-2.4114E-16 -0.34908 9.4518E-16" xyz="0.40319 0 0.16051"/>
    <parent link="Navi_L_V1_link"/>
    <child link="4Gcamera_link"/>
    <axis xyz="0 0 0"/>
  </joint>
  <link name="front_laser_link">
    <inertial>
      <origin rpy="0 0 0" xyz="-0.00019965 -2.9531E-07 0.032148"/>
      <mass value="0.009492"/>
      <inertia ixx="0" ixy="0" ixz="0" iyy="0" iyz="0" izz="0"/>
    </inertial>
    <visual>
      <origin rpy="0 0 0" xyz="0 0 0"/>
      <geometry>
        <mesh filename="package://description_pkg/urdf/meshes/rplidar_s1.STL"/>
      </geometry>
      <material name="">
        <color rgba="0.75294 0.75294 0.75294 1"/>
      </material>
    </visual>
    <collision>
      <origin rpy="0 0 0" xyz="0 0 0"/>
      <geometry>
        <mesh filename="package://description_pkg/urdf/meshes/rplidar_s1.STL"/>
      </geometry>
    </collision>
  </link>
  <joint name="front_laser_joint" type="fixed">
    <origin rpy="0 0 0" xyz="0.4 0 0.0398"/>
    <parent link="Navi_L_V1_link"/>
    <child link="front_laser_link"/>
    <axis xyz="0 0 0"/>
  </joint>
  <link name="back_laser_link">
    <inertial>
      <origin rpy="0 0 0" xyz="-0.00019965 -2.9531E-07 0.032148"/>
      <mass value="0.009492"/>
      <inertia ixx="0" ixy="0" ixz="0" iyy="0" iyz="0" izz="0"/>
    </inertial>
    <visual>
      <origin rpy="0 0 0" xyz="0 0 0"/>
      <geometry>
        <mesh filename="package://description_pkg/urdf/meshes/rplidar_s1.STL"/>
      </geometry>
      <material name="">
        <color rgba="0.75294 0.75294 0.75294 1"/>
      </material>
    </visual>
    <collision>
      <origin rpy="0 0 0" xyz="0 0 0"/>
      <geometry>
        <mesh filename="package://description_pkg/urdf/meshes/rplidar_s1.STL"/>
      </geometry>
    </collision>
  </link>
  <joint name="back_laser_joint" type="fixed">
    <origin rpy="0 0 -3.1416" xyz="-0.4 0 0.0398"/>
    <parent link="Navi_L_V1_link"/>
    <child link="back_laser_link"/>
    <axis xyz="0 0 0"/>
  </joint>
  <link name="1_ultrasonic_link">
    <inertial>
      <origin rpy="0 0 0" xyz="0.0056202 0 0"/>
      <mass value="0.0063918"/>
      <inertia ixx="0" ixy="0" ixz="0" iyy="0" iyz="0" izz="0"/>
    </inertial>
    <visual>
      <origin rpy="0 0 0" xyz="0 0 0"/>
      <geometry>
        <mesh filename="package://description_pkg/urdf/meshes/ult_ks103.STL"/>
      </geometry>
      <material name="">
        <color rgba="0.25098 0.25098 0.25098 1"/>
      </material>
    </visual>
    <collision>
      <origin rpy="0 0 0" xyz="0 0 0"/>
      <geometry>
        <mesh filename="package://description_pkg/urdf/meshes/ult_ks103.STL"/>
      </geometry>
    </collision>
  </link>
  <joint name="1_ultrasonic_joint" type="fixed">
    <origin rpy="0 0 0" xyz="0.4364 0.1145 0.11062"/>
    <parent link="Navi_L_V1_link"/>
    <child link="1_ultrasonic_link"/>
    <axis xyz="0 0 0"/>
  </joint>
  <link name="2_ultrasonic_link">
    <inertial>
      <origin rpy="0 0 0" xyz="0.0056202 0 0"/>
      <mass value="0.0063918"/>
      <inertia ixx="0" ixy="0" ixz="0" iyy="0" iyz="0" izz="0"/>
    </inertial>
    <visual>
      <origin rpy="0 0 0" xyz="0 0 0"/>
      <geometry>
        <mesh filename="package://description_pkg/urdf/meshes/ult_ks103.STL"/>
      </geometry>
      <material name="">
        <color rgba="0.25098 0.25098 0.25098 1"/>
      </material>
    </visual>
    <collision>
      <origin rpy="0 0 0" xyz="0 0 0"/>
      <geometry>
        <mesh filename="package://description_pkg/urdf/meshes/ult_ks103.STL"/>
      </geometry>
    </collision>
  </link>
  <joint name="2_ultrasonic_joint" type="fixed">
    <origin rpy="0 0 1.5708" xyz="0 0.29195 0.1164"/>
    <parent link="Navi_L_V1_link"/>
    <child link="2_ultrasonic_link"/>
    <axis xyz="0 0 0"/>
  </joint>
  <link name="3_ultrasonic_link">
    <inertial>
      <origin rpy="0 0 0" xyz="0.0056202 0 0"/>
      <mass value="0.0063918"/>
      <inertia ixx="0" ixy="0" ixz="0" iyy="0" iyz="0" izz="0"/>
    </inertial>
    <visual>
      <origin rpy="0 0 0" xyz="0 0 0"/>
      <geometry>
        <mesh filename="package://description_pkg/urdf/meshes/ult_ks103.STL"/>
      </geometry>
      <material name="">
        <color rgba="0.25098 0.25098 0.25098 1"/>
      </material>
    </visual>
    <collision>
      <origin rpy="0 0 0" xyz="0 0 0"/>
      <geometry>
        <mesh filename="package://description_pkg/urdf/meshes/ult_ks103.STL"/>
      </geometry>
    </collision>
  </link>
  <joint name="3_ultrasonic_joint" type="fixed">
    <origin rpy="0 0 -3.1416" xyz="-0.4364 0.1145 0.11062"/>
    <parent link="Navi_L_V1_link"/>
    <child link="3_ultrasonic_link"/>
    <axis xyz="0 0 0"/>
  </joint>
  <link name="4_ultrasonic_link">
    <inertial>
      <origin rpy="0 0 0" xyz="0.0056202 0 0"/>
      <mass value="0.0063918"/>
      <inertia ixx="0" ixy="0" ixz="0" iyy="0" iyz="0" izz="0"/>
    </inertial>
    <visual>
      <origin rpy="0 0 0" xyz="0 0 0"/>
      <geometry>
        <mesh filename="package://description_pkg/urdf/meshes/ult_ks103.STL"/>
      </geometry>
      <material name="">
        <color rgba="0.25098 0.25098 0.25098 1"/>
      </material>
    </visual>
    <collision>
      <origin rpy="0 0 0" xyz="0 0 0"/>
      <geometry>
        <mesh filename="package://description_pkg/urdf/meshes/ult_ks103.STL"/>
      </geometry>
    </collision>
  </link>
  <joint name="4_ultrasonic_joint" type="fixed">
    <origin rpy="0 0 3.1416" xyz="-0.4364 -0.1145 0.11062"/>
    <parent link="Navi_L_V1_link"/>
    <child link="4_ultrasonic_link"/>
    <axis xyz="0 0 0"/>
  </joint>
  <link name="5_ultrasonic_link">
    <inertial>
      <origin rpy="0 0 0" xyz="0.0056202 0 0"/>
      <mass value="0.0063918"/>
      <inertia ixx="0" ixy="0" ixz="0" iyy="0" iyz="0" izz="0"/>
    </inertial>
    <visual>
      <origin rpy="0 0 0" xyz="0 0 0"/>
      <geometry>
        <mesh filename="package://description_pkg/urdf/meshes/ult_ks103.STL"/>
      </geometry>
      <material name="">
        <color rgba="0.25098 0.25098 0.25098 1"/>
      </material>
    </visual>
    <collision>
      <origin rpy="0 0 0" xyz="0 0 0"/>
      <geometry>
        <mesh filename="package://description_pkg/urdf/meshes/ult_ks103.STL"/>
      </geometry>
    </collision>
  </link>
  <joint name="5_ultrasonic_joint" type="fixed">
    <origin rpy="0 0 -1.5708" xyz="0 -0.29195 0.1164"/>
    <parent link="Navi_L_V1_link"/>
    <child link="5_ultrasonic_link"/>
    <axis xyz="0 0 0"/>
  </joint>
  <link name="6_ultrasonic_link">
    <inertial>
      <origin rpy="0 0 0" xyz="0.0056202 0 0"/>
      <mass value="0.0063918"/>
      <inertia ixx="0" ixy="0" ixz="0" iyy="0" iyz="0" izz="0"/>
    </inertial>
    <visual>
      <origin rpy="0 0 0" xyz="0 0 0"/>
      <geometry>
        <mesh filename="package://description_pkg/urdf/meshes/ult_ks103.STL"/>
      </geometry>
      <material name="">
        <color rgba="0.25098 0.25098 0.25098 1"/>
      </material>
    </visual>
    <collision>
      <origin rpy="0 0 0" xyz="0 0 0"/>
      <geometry>
        <mesh filename="package://description_pkg/urdf/meshes/ult_ks103.STL"/>
      </geometry>
    </collision>
  </link>
  <joint name="6_ultrasonic_joint" type="fixed">
    <origin rpy="0 0 0" xyz="0.4364 -0.1145 0.11062"/>
    <parent link="Navi_L_V1_link"/>
    <child link="6_ultrasonic_link"/>
    <axis xyz="0 0 0"/>
  </joint>
  <link name="front_bumper_link">
    <inertial>
      <origin rpy="0 0 0" xyz="0.0018383 -1.6277E-16 -2.7756E-17"/>
      <mass value="0.39"/>
      <inertia ixx="7.8534E-33" ixy="2.8025E-19" ixz="4.2661E-20" iyy="1.0748E-05" iyz="-1.1662E-33" izz="1.0748E-05"/>
    </inertial>
    <visual>
      <origin rpy="0 0 0" xyz="0 0 0"/>
      <geometry>
        <mesh filename="package://description_pkg/urdf/meshes/bumper_72.STL"/>
      </geometry>
      <material name="">
        <color rgba="0.79216 0.81961 0.93333 1"/>
      </material>
    </visual>
    <collision>
      <origin rpy="0 0 0" xyz="0 0 0"/>
      <geometry>
        <mesh filename="package://description_pkg/urdf/meshes/bumper_72.STL"/>
      </geometry>
    </collision>
  </link>
  <joint name="front_bumper_joint" type="fixed">
    <origin rpy="0 0 0" xyz="0.455 0 0.021"/>
    <parent link="Navi_L_V1_link"/>
    <child link="front_bumper_link"/>
    <axis xyz="0 0 0"/>
  </joint>
  <link name="back_bumper_link">
    <inertial>
      <origin rpy="0 0 0" xyz="0.0018383 -1.6277E-16 -2.7756E-17"/>
      <mass value="0.39"/>
      <inertia ixx="7.8534E-33" ixy="2.8025E-19" ixz="4.2661E-20" iyy="1.0748E-05" iyz="-1.1662E-33" izz="1.0748E-05"/>
    </inertial>
    <visual>
      <origin rpy="0 0 0" xyz="0 0 0"/>
      <geometry>
        <mesh filename="package://description_pkg/urdf/meshes/bumper_72.STL"/>
      </geometry>
      <material name="">
        <color rgba="0.79216 0.81961 0.93333 1"/>
      </material>
    </visual>
    <collision>
      <origin rpy="0 0 0" xyz="0 0 0"/>
      <geometry>
        <mesh filename="package://description_pkg/urdf/meshes/bumper_72.STL"/>
      </geometry>
    </collision>
  </link>
  <joint name="back_bumper_joint" type="fixed">
    <origin rpy="0 0 3.1415926" xyz="-0.455 0 0.021"/>
    <parent link="Navi_L_V1_link"/>
    <child link="back_bumper_link"/>
    <axis xyz="0 0 0"/>
  </joint>
  <link name="camera_link">
    <inertial>
      <origin rpy="0 0 0" xyz="-0.013048 0.0002462 0"/>
      <mass value="0.044752"/>
      <inertia ixx="0" ixy="0" ixz="0" iyy="0" iyz="0" izz="0"/>
    </inertial>
    <visual>
      <origin rpy="0 0 0" xyz="0 0 0"/>
      <geometry>
        <mesh filename="package://description_pkg/urdf/meshes/realsense_d435.STL"/>
      </geometry>
      <material name="">
        <color rgba="0.79216 0.81961 0.93333 1"/>
      </material>
    </visual>
    <collision>
      <origin rpy="0 0 0" xyz="0 0 0"/>
      <geometry>
        <mesh filename="package://description_pkg/urdf/meshes/realsense_d435.STL"/>
      </geometry>
    </collision>
  </link>
  <joint name="camera_base_joint" type="fixed">
    <origin rpy="0 0 0" xyz="0.45 0 0.11148"/>
    <parent link="Navi_L_V1_link"/>
    <child link="camera_link"/>
    <axis xyz="0 0 0"/>
  </joint>
  <link name="3d_laser_link">
    <inertial>
      <origin rpy="0 0 0" xyz="-5.2047E-09 -1.7921E-10 0.037866"/>
      <mass value="8423.7"/>
      <inertia ixx="3.1592E-06" ixy="6.0256E-12" ixz="-1.421E-06" iyy="5.7747E-06" iyz="-2.9734E-09" izz="2.6155E-06"/>
    </inertial>
    <visual>
      <origin rpy="0 0 0" xyz="0 0 0"/>
      <geometry>
        <mesh filename="package://description_pkg/urdf/meshes/vlp_16.STL"/>
      </geometry>
      <material name="">
        <color rgba="0.79216 0.81961 0.93333 1"/>
      </material>
    </visual>
    <collision>
      <origin rpy="0 0 0" xyz="0 0 0"/>
      <geometry>
        <mesh filename="package://description_pkg/urdf/meshes/vlp_16.STL"/>
      </geometry>
    </collision>
  </link>
  <joint name="3d_laser_joint" type="fixed">
    <origin rpy="0 0 0" xyz="0.34852 0 0.2016"/>
    <parent link="Navi_L_V1_link"/>
    <child link="3d_laser_link"/>
    <axis xyz="0 0 0"/>
  </joint>

 <link name="base_footprint">
  <visual>
    <origin xyz="0 0 0" rpy="0 0 0" />
    <geometry>
      <box size="0.001 0.001 0.001" />
    </geometry>
  </visual>
  </link>
  
  <joint name="base_footprint_joint" type="fixed">
    <origin xyz="0 0 0.033" rpy="0 0 0" />        
    <parent link="base_footprint"/>
    <child link="base_link" />
  </joint> 
</robot>

