<robot name="thunder_mini" xmlns:xacro="http://wiki.ros.org/xacro">
  <link
    name="base_link">
    <xacro:Box_inertial_matrix m="5" l="0.588" w="0.538" h="0.31" />
    <visual>
      <origin
        xyz="0 0 0"
        rpy="0 0 0" />
      <geometry>
        <mesh
          filename="package://description_pkg/urdf/meshes/base_link.STL" />
      </geometry>
      <material
        name="">
        <color
          rgba="1 1 1 1" />
      </material>
    </visual>
    <collision>
      <origin
        xyz="0 0 0"
        rpy="0 0 0" />
      <geometry>
        <mesh
          filename="package://description_pkg/urdf/meshes/base_link.STL" />
      </geometry>
    </collision>
  </link>

  <link
    name="wheel1_link">
    <xacro:cylinder_inertial_matrix m="1" r="0.08" h="0.08" /> 
    <visual>
      <origin
        xyz="0 0 0"
        rpy="0 0 0" />
      <geometry>
        <mesh
          filename="package://description_pkg/urdf/meshes/wheel1_link.STL" />
      </geometry>
      <material
        name="">
        <color
          rgba="0.898039215686275 0.917647058823529 0.929411764705882 1" />
      </material>
    </visual>
    <collision>
      <origin
        xyz="0 0 0"
        rpy="0 0 0" />
      <geometry>
        <mesh
          filename="package://description_pkg/urdf/meshes/wheel1_link.STL" />
      </geometry>
    </collision>
  </link>
  <joint
    name="wheel1_joint"
    type="continuous">
    <origin
      xyz="0.22532 0.2876 0.075478"
      rpy="0 0 0" />
    <parent
      link="base_link" />
    <child
      link="wheel1_link" />
    <axis
      xyz="0 1 0" />
  </joint>
  <link
    name="wheel2_link">
    <xacro:cylinder_inertial_matrix m="1" r="0.08" h="0.08" /> 
    <visual>
      <origin
        xyz="0 0 0"
        rpy="0 0 0" />
      <geometry>
        <mesh
          filename="package://description_pkg/urdf/meshes/wheel2_link.STL" />
      </geometry>
      <material
        name="">
        <color
          rgba="0.898039215686275 0.917647058823529 0.929411764705882 1" />
      </material>
    </visual>
    <collision>
      <origin
        xyz="0 0 0"
        rpy="0 0 0" />
      <geometry>
        <mesh
          filename="package://description_pkg/urdf/meshes/wheel2_link.STL" />
      </geometry>
    </collision>
  </link>
  <joint
    name="wheel2_joint"
    type="continuous">
    <origin
      xyz="0.22533 -0.2876 0.075505"
      rpy="0 0 0" />
    <parent
      link="base_link" />
    <child
      link="wheel2_link" />
    <axis
      xyz="0 1 0" />
  </joint>
  <link
    name="wheel3_link">
    <xacro:cylinder_inertial_matrix m="1" r="0.08" h="0.08" /> 
    <visual>
      <origin
        xyz="0 0 0"
        rpy="0 0 0" />
      <geometry>
        <mesh
          filename="package://description_pkg/urdf/meshes/wheel3_link.STL" />
      </geometry>
      <material
        name="">
        <color
          rgba="0.898039215686275 0.917647058823529 0.929411764705882 1" />
      </material>
    </visual>
    <collision>
      <origin
        xyz="0 0 0"
        rpy="0 0 0" />
      <geometry>
        <mesh
          filename="package://description_pkg/urdf/meshes/wheel3_link.STL" />
      </geometry>
    </collision>
  </link>
  <joint
    name="wheel3_joint"
    type="continuous">
    <origin
      xyz="-0.22532 0.2876 0.075478"
      rpy="0 0 0" />
    <parent
      link="base_link" />
    <child
      link="wheel3_link" />
    <axis
      xyz="0 1 0" />
  </joint>
  <link
    name="wheel4_link">
    <xacro:cylinder_inertial_matrix m="1" r="0.08" h="0.08" /> 
    <visual>
      <origin
        xyz="0 0 0"
        rpy="0 0 0" />
      <geometry>
        <mesh
          filename="package://description_pkg/urdf/meshes/wheel4_link.STL" />
      </geometry>
      <material
        name="">
        <color
          rgba="0.898039215686275 0.917647058823529 0.929411764705882 1" />
      </material>
    </visual>
    <collision>
      <origin
        xyz="0 0 0"
        rpy="0 0 0" />
      <geometry>
        <mesh
          filename="package://description_pkg/urdf/meshes/wheel4_link.STL" />
      </geometry>
    </collision>
  </link>
  <joint
    name="wheel4_joint"
    type="continuous">
    <origin
      xyz="-0.22533 -0.2876 0.075479"
      rpy="0 0 0" />
    <parent
      link="base_link" />
    <child
      link="wheel4_link" />
    <axis
      xyz="0 1 0" />
  </joint>

  <link
    name="laser_link">
    <xacro:cylinder_inertial_matrix m="0.1" r="0.05" h="0.3" />
    <visual>
      <origin
        xyz="0 0 0"
        rpy="0 0 0" />
      <geometry>
        <mesh
          filename="package://description_pkg/urdf/meshes/laser_link.STL" />
      </geometry>
      <material
        name="">
        <color
          rgba="0.298039215686275 0.298039215686275 0.298039215686275 1" />
      </material>
    </visual>
    <collision>
      <origin
        xyz="0 0 0"
        rpy="0 0 0" />
      <geometry>
        <mesh
          filename="package://description_pkg/urdf/meshes/laser_link.STL" />
      </geometry>
    </collision>
  </link>
  <joint
    name="laser_joint"
    type="fixed">
    <origin
      xyz="0.29773 -0.0002012 0.2748"
      rpy="0 0 0" />
    <parent
      link="base_link" />
    <child
      link="laser_link" />
    <axis
      xyz="0 0 0" />
  </joint>
  <link
    name="laser1_link">
    <xacro:cylinder_inertial_matrix m="0.1" r="0.05" h="0.3" />
    <visual>
      <origin
        xyz="0 0 0"
        rpy="0 0 0" />
      <geometry>
        <mesh
          filename="package://description_pkg/urdf/meshes/laser1_link.STL" />
      </geometry>
      <material
        name="">
        <color
          rgba="0.298039215686275 0.298039215686275 0.298039215686275 1" />
      </material>
    </visual>
    <collision>
      <origin
        xyz="0 0 0"
        rpy="0 0 0" />
      <geometry>
        <mesh
          filename="package://description_pkg/urdf/meshes/laser1_link.STL" />
      </geometry>
    </collision>
  </link>
  <joint
    name="laser1_joint"
    type="fixed">
    <origin
      xyz="-0.29773 0.0002012 0.2748"
      rpy="0 0 3.1415926" />
    <parent
      link="base_link" />
    <child
      link="laser1_link" />
    <axis
      xyz="0 0 0" />
    <limit
      lower="0"
      upper="0"
      effort="0"
      velocity="0" />
  </joint>


  <link
    name="imu_link">
    <xacro:Box_inertial_matrix m="0.002" l="0.001" w="0.001" h="0.0001" />
    <visual>
      <origin
        xyz="0 0 0"
        rpy="0 0 0" />
      <geometry>
        <mesh
          filename="package://description_pkg/urdf/meshes/imu_link.STL" />
      </geometry>
      <material
        name="">
        <color
          rgba="0.752941176470588 0.752941176470588 0.752941176470588 1" />
      </material>
    </visual>
    <collision>
      <origin
        xyz="0 0 0"
        rpy="0 0 0" />
      <geometry>
        <mesh
          filename="package://description_pkg/urdf/meshes/imu_link.STL" />
      </geometry>
    </collision>
  </link>
  <joint
    name="imu_joint"
    type="fixed">
    <origin
      xyz="0 0 0"
      rpy="0 0 0" />
    <parent
      link="base_link" />
    <child
      link="imu_link" />
    <axis
      xyz="0 0 0" />
  </joint>

  <link name="base_footprint">
  <visual>
    <origin xyz="0 0 0" rpy="0 0 0" />
    <geometry>
      <box size="0.001 0.001 0.001" />
    </geometry>
  </visual>
  </link>


  <link
    name="camera_link">
    <xacro:Box_inertial_matrix m="0.01" l="0.01" w="0.025" h="0.015" />
    <visual>
      <origin
        xyz="0 0 0"
        rpy="0 0 0" />
      <geometry>
        <mesh
          filename="package://description_pkg/urdf/meshes/camera_link.STL" />
      </geometry>
      <material
        name="">
        <color
          rgba="0.752941176470588 0.752941176470588 0.752941176470588 1" />
      </material>
    </visual>
    <collision>
      <origin
        xyz="0 0 0"
        rpy="0 0 0" />
      <geometry>
        <mesh
          filename="package://description_pkg/urdf/meshes/camera_link.STL" />
      </geometry>
    </collision>
  </link>
  <joint
    name="camera_joint"
    type="fixed">
    <origin
      xyz="0.3442 0 0.31997"
      rpy="0 0 0" />
    <parent
      link="base_link" />
    <child
      link="camera_link" />
    <axis
      xyz="0 0 0" />
  </joint>

  <joint name="base_footprint_joint" type="fixed">
    <origin xyz="0 0 0.033" rpy="0 0 0" />        
    <parent link="base_link"/>
    <child link="base_footprint" />
  </joint> 

    <gazebo reference="wheel1_link">
        <material>Gazebo/Grey</material>
    </gazebo>
    <gazebo reference="wheel2_link">
        <material>Gazebo/Grey</material>
    </gazebo>
    <gazebo reference="wheel3_link">
        <material>Gazebo/Grey</material>
    </gazebo>
    <gazebo reference="wheel4_link">
        <material>Gazebo/Grey</material>
    </gazebo>
   

</robot>

